2020-12-31 12:18:30,679 ERROR: Exception on /auth/login [GET] [in /home/albert/.local/lib/python3.6/site-packages/flask/app.py:1891]
Traceback (most recent call last):
  File "/home/albert/.local/lib/python3.6/site-packages/flask/app.py", line 2446, in wsgi_app
    response = self.full_dispatch_request()
  File "/home/albert/.local/lib/python3.6/site-packages/flask/app.py", line 1951, in full_dispatch_request
    rv = self.handle_user_exception(e)
  File "/home/albert/.local/lib/python3.6/site-packages/flask/app.py", line 1820, in handle_user_exception
    reraise(exc_type, exc_value, tb)
  File "/home/albert/.local/lib/python3.6/site-packages/flask/_compat.py", line 39, in reraise
    raise value
  File "/home/albert/.local/lib/python3.6/site-packages/flask/app.py", line 1949, in full_dispatch_request
    rv = self.dispatch_request()
  File "/home/albert/.local/lib/python3.6/site-packages/flask/app.py", line 1935, in dispatch_request
    return self.view_functions[rule.endpoint](**req.view_args)
  File "/home/albert/Documents/projects/flask_mega_tutorial/microblog/app/auth/routes.py", line 29, in login
    return render_template('auth/login.html', title=_('Sign In'), form=form)
  File "/home/albert/.local/lib/python3.6/site-packages/flask/templating.py", line 140, in render_template
    ctx.app,
  File "/home/albert/.local/lib/python3.6/site-packages/flask/templating.py", line 120, in _render
    rv = template.render(context)
  File "/home/albert/.local/lib/python3.6/site-packages/jinja2/environment.py", line 1090, in render
    self.environment.handle_exception()
  File "/home/albert/.local/lib/python3.6/site-packages/jinja2/environment.py", line 832, in handle_exception
    reraise(*rewrite_traceback_stack(source=source))
  File "/home/albert/.local/lib/python3.6/site-packages/jinja2/_compat.py", line 28, in reraise
    raise value.with_traceback(tb)
  File "/home/albert/Documents/projects/flask_mega_tutorial/microblog/app/templates/auth/login.html", line 2, in top-level template code
    {% import 'bootstrap/wtf.html' as wtf %}
  File "/home/albert/Documents/projects/flask_mega_tutorial/microblog/app/templates/base.html", line 1, in top-level template code
    {% extends 'bootstrap/base.html' %}
  File "/home/albert/.local/lib/python3.6/site-packages/flask_bootstrap/templates/bootstrap/base.html", line 1, in top-level template code
    {% block doc -%}
  File "/home/albert/.local/lib/python3.6/site-packages/flask_bootstrap/templates/bootstrap/base.html", line 3, in block "doc"
    <html{% block html_attribs %}{% endblock html_attribs %}>
  File "/home/albert/.local/lib/python3.6/site-packages/flask_bootstrap/templates/bootstrap/base.html", line 11, in block "html"
    {%- endblock metas %}
  File "/home/albert/.local/lib/python3.6/site-packages/flask_bootstrap/templates/bootstrap/base.html", line 12, in block "body"
  File "/home/albert/Documents/projects/flask_mega_tutorial/microblog/app/templates/base.html", line 17, in block "navbar"
    <a class="navbar-brand" href="{{ url_for('index') }}">Microblog</a>
  File "/home/albert/.local/lib/python3.6/site-packages/flask/helpers.py", line 370, in url_for
    return appctx.app.handle_url_build_error(error, endpoint, values)
  File "/home/albert/.local/lib/python3.6/site-packages/flask/app.py", line 2215, in handle_url_build_error
    reraise(exc_type, exc_value, tb)
  File "/home/albert/.local/lib/python3.6/site-packages/flask/_compat.py", line 39, in reraise
    raise value
  File "/home/albert/.local/lib/python3.6/site-packages/flask/helpers.py", line 358, in url_for
    endpoint, values, method=method, force_external=external
  File "/home/albert/.local/lib/python3.6/site-packages/werkzeug/routing.py", line 2179, in build
    raise BuildError(endpoint, values, method, self)
werkzeug.routing.BuildError: Could not build url for endpoint 'index'. Did you mean 'main.index' instead?
2020-12-31 12:24:58,785 INFO: Microblog startup [in /home/albert/Documents/projects/flask_mega_tutorial/microblog/app/__init__.py:75]
2020-12-31 12:26:25,535 INFO: Microblog startup [in /home/albert/Documents/projects/flask_mega_tutorial/microblog/app/__init__.py:75]
2020-12-31 12:27:35,192 ERROR: Exception on /auth/reset_password_request [POST] [in /home/albert/.local/lib/python3.6/site-packages/flask/app.py:1891]
Traceback (most recent call last):
  File "/home/albert/.local/lib/python3.6/site-packages/flask/app.py", line 2446, in wsgi_app
    response = self.full_dispatch_request()
  File "/home/albert/.local/lib/python3.6/site-packages/flask/app.py", line 1951, in full_dispatch_request
    rv = self.handle_user_exception(e)
  File "/home/albert/.local/lib/python3.6/site-packages/flask/app.py", line 1820, in handle_user_exception
    reraise(exc_type, exc_value, tb)
  File "/home/albert/.local/lib/python3.6/site-packages/flask/_compat.py", line 39, in reraise
    raise value
  File "/home/albert/.local/lib/python3.6/site-packages/flask/app.py", line 1949, in full_dispatch_request
    rv = self.dispatch_request()
  File "/home/albert/.local/lib/python3.6/site-packages/flask/app.py", line 1935, in dispatch_request
    return self.view_functions[rule.endpoint](**req.view_args)
  File "/home/albert/Documents/projects/flask_mega_tutorial/microblog/app/auth/routes.py", line 61, in reset_password_request
    send_password_reset_email(user)
  File "/home/albert/Documents/projects/flask_mega_tutorial/microblog/app/auth/email.py", line 11, in send_password_reset_email
    token = user.get_reset_password_token()
  File "/home/albert/Documents/projects/flask_mega_tutorial/microblog/app/models.py", line 75, in get_reset_password_token
    current_app.config['SECRET_KEY'], algorithm='HS256').decode('utf-8')
AttributeError: 'str' object has no attribute 'decode'
2020-12-31 12:28:38,078 INFO: Microblog startup [in /home/albert/Documents/projects/flask_mega_tutorial/microblog/app/__init__.py:75]
2020-12-31 12:28:49,099 ERROR: Exception on /auth/reset_password_request [POST] [in /home/albert/.local/lib/python3.6/site-packages/flask/app.py:1891]
Traceback (most recent call last):
  File "/home/albert/.local/lib/python3.6/site-packages/flask/app.py", line 2446, in wsgi_app
    response = self.full_dispatch_request()
  File "/home/albert/.local/lib/python3.6/site-packages/flask/app.py", line 1951, in full_dispatch_request
    rv = self.handle_user_exception(e)
  File "/home/albert/.local/lib/python3.6/site-packages/flask/app.py", line 1820, in handle_user_exception
    reraise(exc_type, exc_value, tb)
  File "/home/albert/.local/lib/python3.6/site-packages/flask/_compat.py", line 39, in reraise
    raise value
  File "/home/albert/.local/lib/python3.6/site-packages/flask/app.py", line 1949, in full_dispatch_request
    rv = self.dispatch_request()
  File "/home/albert/.local/lib/python3.6/site-packages/flask/app.py", line 1935, in dispatch_request
    return self.view_functions[rule.endpoint](**req.view_args)
  File "/home/albert/Documents/projects/flask_mega_tutorial/microblog/app/auth/routes.py", line 61, in reset_password_request
    send_password_reset_email(user)
  File "/home/albert/Documents/projects/flask_mega_tutorial/microblog/app/auth/email.py", line 16, in send_password_reset_email
    user=user, token=token),
  File "/home/albert/.local/lib/python3.6/site-packages/flask/templating.py", line 140, in render_template
    ctx.app,
  File "/home/albert/.local/lib/python3.6/site-packages/flask/templating.py", line 120, in _render
    rv = template.render(context)
  File "/home/albert/.local/lib/python3.6/site-packages/jinja2/environment.py", line 1090, in render
    self.environment.handle_exception()
  File "/home/albert/.local/lib/python3.6/site-packages/jinja2/environment.py", line 832, in handle_exception
    reraise(*rewrite_traceback_stack(source=source))
  File "/home/albert/.local/lib/python3.6/site-packages/jinja2/_compat.py", line 28, in reraise
    raise value.with_traceback(tb)
  File "/home/albert/Documents/projects/flask_mega_tutorial/microblog/app/templates/email/reset_password.txt", line 5, in top-level template code
    {{ url_for('reset_password', token=token, _external=True) }}
  File "/home/albert/.local/lib/python3.6/site-packages/flask/helpers.py", line 370, in url_for
    return appctx.app.handle_url_build_error(error, endpoint, values)
  File "/home/albert/.local/lib/python3.6/site-packages/flask/app.py", line 2215, in handle_url_build_error
    reraise(exc_type, exc_value, tb)
  File "/home/albert/.local/lib/python3.6/site-packages/flask/_compat.py", line 39, in reraise
    raise value
  File "/home/albert/.local/lib/python3.6/site-packages/flask/helpers.py", line 358, in url_for
    endpoint, values, method=method, force_external=external
  File "/home/albert/.local/lib/python3.6/site-packages/werkzeug/routing.py", line 2179, in build
    raise BuildError(endpoint, values, method, self)
werkzeug.routing.BuildError: Could not build url for endpoint 'reset_password' with values ['token']. Did you mean 'auth.reset_password' instead?
